{"start": 1587390557698, "befores": [{"name": "_Class__pytest_setup_class", "start": 1587390557698, "status": "broken", "stop": 1587390562723, "statusDetails": {"message": "urllib3.exceptions.MaxRetryError: HTTPConnectionPool(host='127.0.0.1', port=4723): Max retries exceeded with url: /wd/hub/session (Caused by NewConnectionError('<urllib3.connection.HTTPConnection object at 0x00000000044B97B8>: Failed to establish a new connection: [WinError 10061] 由于目标计算机积极拒绝，无法连接。',))\n", "trace": "  File \"d:\\python\\python35\\lib\\site-packages\\pluggy\\callers.py\", line 187, in _multicall\n    res = hook_impl.function(*args)\n  File \"d:\\python\\python35\\lib\\site-packages\\_pytest\\fixtures.py\", line 964, in pytest_fixture_setup\n    result = call_fixture_func(fixturefunc, request, kwargs)\n  File \"d:\\python\\python35\\lib\\site-packages\\_pytest\\fixtures.py\", line 788, in call_fixture_func\n    res = next(it)\n  File \"d:\\python\\python35\\lib\\site-packages\\_pytest\\python.py\", line 703, in xunit_setup_class_fixture\n    _call_with_optional_argument(func, self.obj)\n  File \"d:\\python\\python35\\lib\\site-packages\\_pytest\\python.py\", line 634, in _call_with_optional_argument\n    func(arg)\n  File \"D:\\untitled\\tnar_obj\\scripts\\test_setting.py\", line 15, in setup_class\n    self.driver=init_driver()\n  File \"D:\\untitled\\tnar_obj\\Base\\init_driver.py\", line 18, in init_driver\n    driver = webdriver.Remote('http://127.0.0.1:4723/wd/hub', desired_caps)\n  File \"d:\\python\\python35\\lib\\site-packages\\appium\\webdriver\\webdriver.py\", line 151, in __init__\n    proxy\n  File \"d:\\python\\python35\\lib\\site-packages\\selenium\\webdriver\\remote\\webdriver.py\", line 157, in __init__\n    self.start_session(capabilities, browser_profile)\n  File \"d:\\python\\python35\\lib\\site-packages\\appium\\webdriver\\webdriver.py\", line 227, in start_session\n    response = self.execute(RemoteCommand.NEW_SESSION, parameters)\n  File \"d:\\python\\python35\\lib\\site-packages\\selenium\\webdriver\\remote\\webdriver.py\", line 319, in execute\n    response = self.command_executor.execute(driver_command, params)\n  File \"d:\\python\\python35\\lib\\site-packages\\selenium\\webdriver\\remote\\remote_connection.py\", line 374, in execute\n    return self._request(command_info[0], url, body=data)\n  File \"d:\\python\\python35\\lib\\site-packages\\selenium\\webdriver\\remote\\remote_connection.py\", line 397, in _request\n    resp = self._conn.request(method, url, body=body, headers=headers)\n  File \"d:\\python\\python35\\lib\\site-packages\\urllib3\\request.py\", line 80, in request\n    method, url, fields=fields, headers=headers, **urlopen_kw\n  File \"d:\\python\\python35\\lib\\site-packages\\urllib3\\request.py\", line 171, in request_encode_body\n    return self.urlopen(method, url, **extra_kw)\n  File \"d:\\python\\python35\\lib\\site-packages\\urllib3\\poolmanager.py\", line 330, in urlopen\n    response = conn.urlopen(method, u.request_uri, **kw)\n  File \"d:\\python\\python35\\lib\\site-packages\\urllib3\\connectionpool.py\", line 760, in urlopen\n    **response_kw\n  File \"d:\\python\\python35\\lib\\site-packages\\urllib3\\connectionpool.py\", line 760, in urlopen\n    **response_kw\n  File \"d:\\python\\python35\\lib\\site-packages\\urllib3\\connectionpool.py\", line 760, in urlopen\n    **response_kw\n  File \"d:\\python\\python35\\lib\\site-packages\\urllib3\\connectionpool.py\", line 720, in urlopen\n    method, url, error=e, _pool=self, _stacktrace=sys.exc_info()[2]\n  File \"d:\\python\\python35\\lib\\site-packages\\urllib3\\util\\retry.py\", line 436, in increment\n    raise MaxRetryError(_pool, url, error or ResponseError(cause))\n"}}], "stop": 1587390563409, "children": ["90fc4efe-8df4-4e2c-9acf-6ee096a39638", "eec3448d-b363-4a48-a04f-5fd3015d0d0e", "8f9ddd8e-05a6-49e5-b20c-a834c843b391"], "uuid": "77185619-bcaf-4f5d-b081-f990fd74f7e5"}